{
    "registryname": "alloy_decomposer",
    "localizedname": "合金分解机",
    "color": "424242",
    "modifiers": [
        {
            "elements": "modularmachinery:blockcasing@1",
            "x": 0,
            "y": 1,
            "z": 0,
            "description": "将控制器上方紧挨着的方块换成机械升级方块以提高机器运转速度！",
            "modifier": {
                "io": "output",
                "target": "duration",
                "operation": 1,
                "multiplier": 0.75
            }
        },
        {
            "elements": "modularmachinery:blockcasing@2",
            "x": 0,
            "y": 1,
            "z": 0,
            "description": "将控制器上方紧挨着的方块换成机械升级方块以提高机器运转速度！",
            "modifier": {
                "io": "output",
                "target": "duration",
                "operation": 1,
                "multiplier": 0.66
            }
        },
        {
            "elements": "modularmachinery:blockcasing@3",
            "x": 0,
            "y": 1,
            "z": 0,
            "description": "将控制器上方紧挨着的方块换成机械升级方块以提高机器运转速度！",
            "modifier": {
                "io": "output",
                "target": "duration",
                "operation": 1,
                "multiplier": 0.5
            }
        },
        {
            "elements": "modularmachinery:blockcasing@5",
            "x": 0,
            "y": 1,
            "z": 0,
            "description": "将控制器上方紧挨着的方块换成机械升级方块以提高机器运转速度！",
            "modifier": {
                "io": "output",
                "target": "duration",
                "operation": 1,
                "multiplier": 0.33
            }
        }
    ],
    "parts": [
        {
            "x": -2,
            "y": 0,
            "z": 2,
            "elements": "casings_all"
        },
        {
            "x": -1,
            "y": 2,
            "z": 3,
            "elements": "casings_seared"
        },
        {
            "x": -1,
            "y": 0,
            "z": 0,
            "elements": "casings_all"
        },
        {
            "x": 1,
            "y": 2,
            "z": 1,
            "elements": "casings_seared"
        },
        {
            "x": 0,
            "y": 2,
            "z": 3,
            "elements": "casings_seared"
        },
        {
            "x": 1,
            "y": 0,
            "z": 0,
            "elements": "casings_all"
        },
        {
            "x": 1,
            "y": 2,
            "z": 3,
            "elements": "casings_seared"
        },
        {
            "x": -1,
            "y": -2,
            "z": 1,
            "elements": "casings_seared"
        },
        {
            "x": 0,
            "y": -2,
            "z": 1,
            "elements": "casings_seared"
        },
        {
            "x": -1,
            "y": 0,
            "z": 4,
            "elements": "casings_all"
        },
        {
            "x": 2,
            "y": 0,
            "z": 2,
            "elements": "casings_all"
        },
        {
            "x": -1,
            "y": -2,
            "z": 3,
            "elements": "casings_seared"
        },
        {
            "x": 1,
            "y": -2,
            "z": 1,
            "elements": "casings_seared"
        },
        {
            "x": 0,
            "y": 0,
            "z": 4,
            "elements": "casings_all"
        },
        {
            "x": 1,
            "y": 0,
            "z": 4,
            "elements": "casings_all"
        },
        {
            "x": 0,
            "y": -2,
            "z": 3,
            "elements": "casings_seared"
        },
        {
            "x": 1,
            "y": -2,
            "z": 3,
            "elements": "casings_seared"
        },
        {
            "x": 1,
            "y": -1,
            "z": 0,
            "elements": "casings_seared"
        },
        {
            "x": 0,
            "y": -1,
            "z": 0,
            "elements": "casings_seared"
        },
        {
            "x": -1,
            "y": 1,
            "z": 0,
            "elements": "casings_seared"
        },
        {
            "x": 0,
            "y": 1,
            "z": 0,
            "elements": "casings_seared"
        },
        {
            "x": -1,
            "y": -1,
            "z": 0,
            "elements": "casings_seared"
        },
        {
            "x": -2,
            "y": 1,
            "z": 2,
            "elements": "casings_seared"
        },
        {
            "x": -2,
            "y": -1,
            "z": 1,
            "elements": "casings_seared"
        },
        {
            "x": 1,
            "y": 1,
            "z": 0,
            "elements": "casings_seared"
        },
        {
            "x": -2,
            "y": -1,
            "z": 3,
            "elements": "casings_seared"
        },
        {
            "x": -1,
            "y": 1,
            "z": 4,
            "elements": "casings_seared"
        },
        {
            "x": 0,
            "y": 1,
            "z": 4,
            "elements": "casings_seared"
        },
        {
            "x": 2,
            "y": 1,
            "z": 2,
            "elements": "casings_seared"
        },
        {
            "x": 1,
            "y": 1,
            "z": 4,
            "elements": "casings_seared"
        },
        {
            "x": 2,
            "y": -1,
            "z": 1,
            "elements": "casings_seared"
        },
        {
            "x": 2,
            "y": -1,
            "z": 3,
            "elements": "casings_seared"
        },
        {
            "x": -2,
            "y": 0,
            "z": 1,
            "elements": "casings_all"
        },
        {
            "x": -1,
            "y": 2,
            "z": 2,
            "elements": "casings_seared"
        },
        {
            "x": 0,
            "y": 2,
            "z": 2,
            "elements": "casings_seared"
        },
        {
            "x": -2,
            "y": 0,
            "z": 3,
            "elements": "casings_all"
        },
        {
            "x": 1,
            "y": 2,
            "z": 2,
            "elements": "casings_seared"
        },
        {
            "x": -1,
            "y": -2,
            "z": 2,
            "elements": "casings_seared"
        },
        {
            "x": 2,
            "y": 0,
            "z": 1,
            "elements": "casings_all"
        },
        {
            "x": 0,
            "y": -2,
            "z": 2,
            "elements": "casings_seared"
        },
        {
            "x": 1,
            "y": -2,
            "z": 2,
            "elements": "casings_seared"
        },
        {
            "x": 2,
            "y": 0,
            "z": 3,
            "elements": "casings_all"
        },
        {
            "x": -2,
            "y": 1,
            "z": 1,
            "elements": "casings_seared"
        },
        {
            "x": -2,
            "y": 1,
            "z": 3,
            "elements": "casings_seared"
        },
        {
            "x": -2,
            "y": -1,
            "z": 2,
            "elements": "casings_seared"
        },
        {
            "x": 2,
            "y": 1,
            "z": 1,
            "elements": "casings_seared"
        },
        {
            "x": 2,
            "y": 1,
            "z": 3,
            "elements": "casings_seared"
        },
        {
            "x": -1,
            "y": -1,
            "z": 4,
            "elements": "casings_seared"
        },
        {
            "x": 0,
            "y": -1,
            "z": 4,
            "elements": "casings_seared"
        },
        {
            "x": 2,
            "y": -1,
            "z": 2,
            "elements": "casings_seared"
        },
        {
            "x": 1,
            "y": -1,
            "z": 4,
            "elements": "casings_seared"
        },
        {
            "x": -1,
            "y": 2,
            "z": 1,
            "elements": "casings_seared"
        },
        {
            "x": 0,
            "y": 2,
            "z": 1,
            "elements": "casings_seared"
        }
    ]
}
