{
    "registryname": "organic_infuser",
    "localizedname": "Organic Infuser",
    "color": "8bc34a",
    "modifiers": [
        {
            "elements": "modularmachinery:blockcasing@1",
            "x": 0,
            "y": 1,
            "z": 0,
            "description": "Replace the block right on top of the controller into any of the machine upgraders to increase byproduct production rate!",
            "modifier": {
                "io": "output",
                "target": "item",
                "operation": 1,
                "multiplier": 1.5,
                "affectChance": true
            }
        },
        {
            "elements": "modularmachinery:blockcasing@2",
            "x": 0,
            "y": 1,
            "z": 0,
            "description": "Replace the block right on top of the controller into any of the machine upgraders to increase byproduct production rate!",
            "modifier": {
                "io": "output",
                "target": "item",
                "operation": 1,
                "multiplier": 2,
                "affectChance": true
            }
        },
        {
            "elements": "modularmachinery:blockcasing@3",
            "x": 0,
            "y": 1,
            "z": 0,
            "description": "Replace the block right on top of the controller into any of the machine upgraders to increase byproduct production rate!",
            "modifier": {
                "io": "output",
                "target": "item",
                "operation": 1,
                "multiplier": 2.5,
                "affectChance": true
            }
        },
        {
            "elements": "modularmachinery:blockcasing@5",
            "x": 0,
            "y": 1,
            "z": 0,
            "description": "Replace the block right on top of the controller into any of the machine upgraders to increase byproduct production rate!",
            "modifier": {
                "io": "output",
                "target": "item",
                "operation": 1,
                "multiplier": 3,
                "affectChance": true
            }
        }
    ],
    "parts": [
        {
            "x": -2,
            "y": 0,
            "z": 2,
            "elements": ["minecraft:glass@0"]
        },
        {
            "x": -1,
            "y": 0,
            "z": 0,
            "elements": "casings_all"
        },
        {
            "x": -1,
            "y": 2,
            "z": 3,
            "elements": ["minecraft:glass@0"]
        },
        {
            "x": 1,
            "y": 2,
            "z": 1,
            "elements": ["minecraft:glass@0"]
        },
        {
            "x": 1,
            "y": 0,
            "z": 0,
            "elements": "casings_all"
        },
        {
            "x": 0,
            "y": 2,
            "z": 3,
            "elements": ["minecraft:glass@0"]
        },
        {
            "x": -1,
            "y": -2,
            "z": 1,
            "elements": ["modularmachinery:blockcasing@4"]
        },
        {
            "x": 1,
            "y": 2,
            "z": 3,
            "elements": ["minecraft:glass@0"]
        },
        {
            "x": 0,
            "y": -2,
            "z": 1,
            "elements": ["modularmachinery:blockcasing@4"]
        },
        {
            "x": -1,
            "y": 0,
            "z": 4,
            "elements": "casings_all"
        },
        {
            "x": -1,
            "y": -2,
            "z": 3,
            "elements": ["modularmachinery:blockcasing@4"]
        },
        {
            "x": 1,
            "y": -2,
            "z": 1,
            "elements": ["modularmachinery:blockcasing@4"]
        },
        {
            "x": 2,
            "y": 0,
            "z": 2,
            "elements": ["minecraft:glass@0"]
        },
        {
            "x": 0,
            "y": 0,
            "z": 4,
            "elements": ["minecraft:glass@0"]
        },
        {
            "x": 0,
            "y": -2,
            "z": 3,
            "elements": ["modularmachinery:blockcasing@4"]
        },
        {
            "x": 1,
            "y": 0,
            "z": 4,
            "elements": "casings_all"
        },
        {
            "x": 1,
            "y": -2,
            "z": 3,
            "elements": ["modularmachinery:blockcasing@4"]
        },
        {
            "x": 1,
            "y": -1,
            "z": 0,
            "elements": "casings_all"
        },
        {
            "x": 0,
            "y": -1,
            "z": 0,
            "elements": ["mysticalagriculture:storage@4"]
        },
        {
            "x": -1,
            "y": 1,
            "z": 0,
            "elements": ["modularmachinery:blockcasing@4"]
        },
        {
            "x": -2,
            "y": 1,
            "z": 2,
            "elements": ["modularmachinery:blockcasing@4"]
        },
        {
            "x": -1,
            "y": -1,
            "z": 0,
            "elements": "casings_all"
        },
        {
            "x": 0,
            "y": 1,
            "z": 0,
            "elements": ["modularmachinery:blockcasing@4"]
        },
        {
            "x": -2,
            "y": -1,
            "z": 1,
            "elements": "casings_all"
        },
        {
            "x": 1,
            "y": 1,
            "z": 0,
            "elements": ["modularmachinery:blockcasing@4"]
        },
        {
            "x": -1,
            "y": -1,
            "z": 1,
            "elements": ["mysticalagriculture:growth_accelerator@0"]
        },
        {
            "x": -1,
            "y": 1,
            "z": 4,
            "elements": ["modularmachinery:blockcasing@4"]
        },
        {
            "x": -2,
            "y": -1,
            "z": 3,
            "elements": "casings_all"
        },
        {
            "x": 0,
            "y": -1,
            "z": 1,
            "elements": ["mysticalagriculture:growth_accelerator@0"]
        },
        {
            "x": 2,
            "y": 1,
            "z": 2,
            "elements": ["modularmachinery:blockcasing@4"]
        },
        {
            "x": 0,
            "y": 1,
            "z": 4,
            "elements": ["modularmachinery:blockcasing@4"]
        },
        {
            "x": -1,
            "y": -1,
            "z": 3,
            "elements": ["mysticalagriculture:growth_accelerator@0"]
        },
        {
            "x": 1,
            "y": -1,
            "z": 1,
            "elements": ["mysticalagriculture:growth_accelerator@0"]
        },
        {
            "x": 2,
            "y": -1,
            "z": 1,
            "elements": "casings_all"
        },
        {
            "x": 1,
            "y": 1,
            "z": 4,
            "elements": ["modularmachinery:blockcasing@4"]
        },
        {
            "x": 0,
            "y": -1,
            "z": 3,
            "elements": ["mysticalagriculture:growth_accelerator@0"]
        },
        {
            "x": 1,
            "y": -1,
            "z": 3,
            "elements": ["mysticalagriculture:growth_accelerator@0"]
        },
        {
            "x": 2,
            "y": -1,
            "z": 3,
            "elements": "casings_all"
        },
        {
            "x": -2,
            "y": 0,
            "z": 1,
            "elements": "casings_all"
        },
        {
            "x": -1,
            "y": 2,
            "z": 2,
            "elements": ["minecraft:glass@0"]
        },
        {
            "x": 0,
            "y": 2,
            "z": 2,
            "elements": ["minecraft:glass@0"]
        },
        {
            "x": -2,
            "y": 0,
            "z": 3,
            "elements": "casings_all"
        },
        {
            "x": 1,
            "y": 2,
            "z": 2,
            "elements": ["minecraft:glass@0"]
        },
        {
            "x": -1,
            "y": -2,
            "z": 2,
            "elements": ["modularmachinery:blockcasing@4"]
        },
        {
            "x": 2,
            "y": 0,
            "z": 1,
            "elements": "casings_all"
        },
        {
            "x": 0,
            "y": -2,
            "z": 2,
            "elements": ["modularmachinery:blockcasing@4"]
        },
        {
            "x": 1,
            "y": -2,
            "z": 2,
            "elements": ["modularmachinery:blockcasing@4"]
        },
        {
            "x": 2,
            "y": 0,
            "z": 3,
            "elements": "casings_all"
        },
        {
            "x": -2,
            "y": 1,
            "z": 1,
            "elements": ["modularmachinery:blockcasing@4"]
        },
        {
            "x": -2,
            "y": 1,
            "z": 3,
            "elements": ["modularmachinery:blockcasing@4"]
        },
        {
            "x": -2,
            "y": -1,
            "z": 2,
            "elements": ["mysticalagriculture:storage@4"]
        },
        {
            "x": 2,
            "y": 1,
            "z": 1,
            "elements": ["modularmachinery:blockcasing@4"]
        },
        {
            "x": -1,
            "y": -1,
            "z": 2,
            "elements": ["mysticalagriculture:growth_accelerator@0"]
        },
        {
            "x": 0,
            "y": -1,
            "z": 2,
            "elements": ["minecraft:diamond_block@0"]
        },
        {
            "x": 2,
            "y": 1,
            "z": 3,
            "elements": ["modularmachinery:blockcasing@4"]
        },
        {
            "x": -1,
            "y": -1,
            "z": 4,
            "elements": "casings_all"
        },
        {
            "x": 1,
            "y": -1,
            "z": 2,
            "elements": ["mysticalagriculture:growth_accelerator@0"]
        },
        {
            "x": 2,
            "y": -1,
            "z": 2,
            "elements": ["mysticalagriculture:storage@4"]
        },
        {
            "x": 0,
            "y": -1,
            "z": 4,
            "elements": ["mysticalagriculture:storage@4"]
        },
        {
            "x": 1,
            "y": -1,
            "z": 4,
            "elements": "casings_all"
        },
        {
            "x": -1,
            "y": 2,
            "z": 1,
            "elements": ["minecraft:glass@0"]
        },
        {
            "x": 0,
            "y": 2,
            "z": 1,
            "elements": ["minecraft:glass@0"]
        }
    ]
}
